<?xml version="1.0"?>
<robot  name="ar3" >
 <material  name="Black" >
  <color  rgba="0 0 0 1" />
 </material>
 <material  name="Blue" >
  <color  rgba="0.0 0.0 0.8 1.0" />
 </material>
 <material  name="Green" >
  <color  rgba="0.0 0.8 0.0 1.0" />
 </material>
 <material  name="Grey" >
  <color  rgba="0.4 0.4 0.4 1.0" />
 </material>
 <material  name="White" >
  <color  rgba="1.0 1.0 1.0 1.0" />
 </material>
 <material  name="Red" >
  <color  rgba="0.8 0.0 0.0 1.0" />
 </material>
 <material  name="Yellow" >
  <color  rgba="1 1 0 1" />
 </material>
 <material  name="gripper_base_color" >
  <color  rgba="0.0 0.8 0.0 1.0" />
 </material>
 <material  name="fingers_color" >
  <color  rgba="0.0 0.8 0.0 1.0" />
 </material>
 <gazebo >
  <plugin  name="gazebo_ros_control"  filename="libgazebo_ros_control.so" />
 </gazebo>
 <link  name="world" />
 <joint  name="world_joint"  type="fixed" >
  <parent  link="world" />
  <child  link="ar3_base_link" />
  <origin  rpy="0 0 0"  xyz="0 0 0" />
 </joint>
 <gazebo    reference="ar3_base_link" >
  <material  name="Gazebo/Red" />
 </gazebo>
 <gazebo    reference="link_1" >
  <material  name="Gazebo/Grey" />
 </gazebo>
 <gazebo    reference="link_2" >
  <material  name="Gazebo/Grey" />
 </gazebo>
 <gazebo    reference="link_3" >
  <material  name="Gazebo/Grey" />
 </gazebo>
 <gazebo    reference="link_5" >
  <material  name="Gazebo/Grey" />
 </gazebo>
 <gazebo    reference="link_6" >
  <material  name="Gazebo/Grey" />
 </gazebo>
 <gazebo />
 <link  name="ar3_base_link" >
  <inertial >
   <mass  value="0.7102" />
   <origin  xyz="-4.6941E-06 0.054174 0.038824"  rpy="0 0 0" />
   <inertia  izz="0.0042554"  iyy="0.0014946"  ixx="0.0039943"  ixy="3.697E-07"  iyz="-0.00036051"  ixz="-5.7364E-08" />
  </inertial>
  <visual >
   <origin  xyz="0 0 0"  rpy="0 0 0" />
   <geometry  name="baselink geometry" >
    <mesh  filename="package://ar3_description/meshes/base_link.STL" scale="1 1 1" />
   </geometry>
   <material  name="Yellow" />
  </visual>
  <collision >
   <origin  xyz="0 0 0"  rpy="0 0 0" />
   <geometry >
    <mesh  filename="package://ar3_description/meshes/base_link.STL" scale="1 1 1" />
   </geometry>
  </collision>
 </link>
 <link  name="link_1" >
  <inertial >
   <mass  value="0.88065" />
   <origin  xyz="-0.022706 0.04294 -0.12205"  rpy="0 0 0" />
   <inertia  izz="0.0027077"  iyy="0.0041778"  ixx="0.0034"  ixy="0.00042296"  iyz="0.0010848"  ixz="-0.00089231" />
  </inertial>
  <visual >
   <origin  xyz="0 0 0"  rpy="0 0 0" />
   <geometry  name="link_1 geometry" >
    <mesh  filename="package://ar3_description/meshes/link_1.STL" scale="1 1 1" />
   </geometry>
   <material  name="Yellow" />
  </visual>
  <collision >
   <origin  xyz="0 0 0"  rpy="0 0 0" />
   <geometry >
    <mesh  filename="package://ar3_description/meshes/link_1.STL" scale="1 1 1" />
   </geometry>
  </collision>
 </link>
 <link  name="link_2" >
  <inertial >
   <mass  value="0.57738" />
   <origin  xyz="0.064818 -0.11189 -0.038671"  rpy="0 0 0" />
   <inertia  izz="0.0056129"  iyy="0.0020836"  ixx="0.0047312"  ixy="0.0022624"  iyz="-0.00056569"  ixz="0.00032144" />
  </inertial>
  <visual >
   <origin  xyz="0 0 0"  rpy="0 0 0" />
   <geometry  name="link_2 geometry" >
    <mesh  filename="package://ar3_description/meshes/link_2.STL" scale="1 1 1" />
   </geometry>
   <material  name="Yellow" />
  </visual>
  <collision >
   <origin  xyz="0 0 0"  rpy="0 0 0" />
   <geometry >
    <mesh  filename="package://ar3_description/meshes/link_2.STL" scale="1 1 1" />
   </geometry>
  </collision>
 </link>
 <link  name="link_3" >
  <inertial >
   <mass  value="0.1787" />
   <origin  xyz="-0.00029765 -0.023661 -0.0019125"  rpy="0 0 0" />
   <inertia  izz="0.00020744"  iyy="0.00012865"  ixx="0.0001685"  ixy="-2.7713E-05"  iyz="2.9256E-05"  ixz="5.6885E-06" />
  </inertial>
  <visual >
   <origin  xyz="0 0 0"  rpy="0 0 0" />
   <geometry  name="link_3 geometry" >
    <mesh  filename="package://ar3_description/meshes/link_3.STL" scale="1 1 1" />
   </geometry>
   <material  name="Yellow" />
  </visual>
  <collision >
   <origin  xyz="0 0 0"  rpy="0 0 0" />
   <geometry >
    <mesh  filename="package://ar3_description/meshes/link_3.STL" scale="1 1 1" />
   </geometry>
  </collision>
 </link>
 <link  name="link_4" >
  <inertial >
   <mass  value="0.34936" />
   <origin  xyz="-0.0016798 -0.00057319 -0.074404"  rpy="0 0 0" />
   <inertia  izz="0.00022264"  iyy="0.0031033"  ixx="0.0030532"  ixy="-1.8615E-05"  iyz="-2.3301E-05"  ixz="-7.0047E-05" />
  </inertial>
  <visual >
   <origin  xyz="0 0 0"  rpy="0 0 0" />
   <geometry  name="link_4 geometry" >
    <mesh  filename="package://ar3_description/meshes/link_4.STL" scale="1 1 1" />
   </geometry>
   <material  name="Yellow" />
  </visual>
  <collision >
   <origin  xyz="0 0 0"  rpy="0 0 0" />
   <geometry >
    <mesh  filename="package://ar3_description/meshes/link_4.STL" scale="1 1 1" />
   </geometry>
  </collision>
 </link>
 <link  name="link_5" >
  <inertial >
   <mass  value="0.11562" />
   <origin  xyz="0.0015066 -1.3102E-05 -0.012585"  rpy="0 0 0" />
   <inertia  izz="5.2518E-05"  iyy="8.2921E-05"  ixx="5.5035E-05"  ixy="-1.019E-08"  iyz="1.4437E-08"  ixz="-2.6243E-06" />
  </inertial>
  <visual >
   <origin  xyz="0 0 0"  rpy="0 0 0" />
   <geometry  name="link_5 geometry" >
    <mesh  filename="package://ar3_description/meshes/link_5.STL" scale="1 1 1" />
   </geometry>
   <material  name="Yellow" />
  </visual>
  <collision >
   <origin  xyz="0 0 0"  rpy="0 0 0" />
   <geometry >
    <mesh  filename="package://ar3_description/meshes/link_5.STL" scale="1 1 1" />
   </geometry>
  </collision>
 </link>
 <link  name="link_6" >
  <inertial >
   <mass  value="0.013863" />
   <origin  xyz="2.9287E-10 -1.6472E-09 0.0091432"  rpy="0 0 0" />
   <inertia  izz="2.4332e-06"  iyy="1.7157e-06"  ixx="1.3596e-06"  ixy="3.0585e-13"  iyz="6.3369e-09"  ixz="5.7102e-14" />
  </inertial>
  <visual >
   <origin  xyz="0 0 0"  rpy="0 0 0" />
   <geometry  name="link_6 geometry" >
    <mesh  filename="package://ar3_description/meshes/link_6.STL" scale="1 1 1" />
   </geometry>
   <material  name="Yellow" />
  </visual>
  <collision >
   <origin  xyz="0 0 0"  rpy="0 0 0" />
   <geometry >
    <mesh  filename="package://ar3_description/meshes/link_6.STL" scale="1 1 1" />
   </geometry>
  </collision>
 </link>
 <link  name="ar3_end_link" >
  <inertial >
   <mass  value="0.01" />
   <origin  xyz="0.0123620482957 4.04067993065027E-06 6.38421238097209E-09"  rpy="0 0 0" />
   <inertia  izz="0.001171"  iyy="0.001110"  ixx="0.000380"  ixy="0.000000"  iyz="0.000000"  ixz="0.000000" />
  </inertial>
  <visual >
   <origin  xyz="0 0 0"  rpy="0 0 0" />
   <geometry  name="box_geometry" >
    <box  size="0.002 0.002 0.002" />
   </geometry>
   <material  name="Black" />
  </visual>
  <collision >
   <origin  xyz="0 0 0"  rpy="0 0 0" />
   <geometry >
    <box  size="0.002 0.002 0.002" />
   </geometry>
  </collision>
 </link>
 <joint  name="ar3_base_link_joint"  type="revolute" >
  <axis  xyz="0 0 1" />
  <limit  effort="100"  lower="-2.96706"  velocity="100"  upper="2.96706" />
  <dynamics  friction="0.1"  damping="0.0" />
  <origin  xyz="0 0 0.003445"  rpy="3.141516 0 0" />
  <parent  link="ar3_base_link" />
  <child  link="link_1" />
 </joint>
 <joint  name="joint_2"  type="revolute" >
  <axis  xyz="0 0 -1" />
  <limit  effort="100"  lower="-0.07002801"  velocity="100"  upper="1.570758" />
  <dynamics  friction="0.1"  damping="0.0" />
  <origin  xyz="0 0.064146 -0.16608"  rpy="1.5708 0.5236 -1.5708" />
  <parent  link="link_1" />
  <child  link="link_2" />
 </joint>
 <joint  name="joint_3"  type="revolute" >
  <axis  xyz="0 0 -1" />
  <limit  effort="100"  lower="0.0174533"  velocity="100"  upper="2.5080381" />
  <dynamics  friction="0.1"  damping="0.0" />
  <origin  xyz="0.1525 -0.26414 0"  rpy="3.3431E-16 -1.4164E-16 -1.4953816339" />
  <parent  link="link_2" />
  <child  link="link_3" />
 </joint>
 <joint  name="joint_4"  type="revolute" >
  <axis  xyz="0 0 -1" />
  <limit  effort="100"  lower="-2.8710666"  velocity="100"  upper="2.8710666" />
  <dynamics  friction="0.1"  damping="0.0" />
  <origin  xyz="0 0 0.00675"  rpy="1.5708 -1.2554 -1.5708" />
  <parent  link="link_3" />
  <child  link="link_4" />
 </joint>
 <joint  name="joint_5"  type="revolute" >
  <axis  xyz="1 0 0" />
  <limit  effort="100"  lower="-1.81776042"  velocity="100"  upper="1.81776042" />
  <dynamics  friction="0.6"  damping="0.0" />
  <origin  xyz="0 0 -0.22225"  rpy="3.1416 0 -2.8262" />
  <parent  link="link_4" />
  <child  link="link_5" />
 </joint>
 <joint  name="joint_6"  type="revolute" >
  <axis  xyz="0 0 1" />
  <limit  effort="100"  lower="-2.5848326"  velocity="100"  upper="2.5848326" />
  <dynamics  friction="0.6"  damping="0.0" />
  <origin  xyz="-0.000294 0 0.02117"  rpy="0 0 0" />
  <parent  link="link_5" />
  <child  link="link_6" />
 </joint>
 <joint  name="ar3_end_link_joint"  type="fixed" >
  <axis  xyz="0 0 0" />
  <limit  effort="30"  lower="0.0"  velocity="1.0"  upper="3.14" />
  <dynamics  friction="0.0"  damping="0.0" />
  <origin  xyz="0.0175 -0.0090 -0.0110"  rpy="0 0 0.0365" />
  <parent  link="link_6" />
  <child  link="ar3_end_link" />
 </joint>
 <transmission  name="trans_joint_1" >
  <type >
   transmission_interface/SimpleTransmission
  </type>
  <joint  name="ar3_base_link_joint" >
   <hardwareInterface >
    hardware_interface/PositionJointInterface
   </hardwareInterface>
  </joint>
  <actuator  name="motor_joint_1" >
   <mechanicalReduction >
    1
   </mechanicalReduction>
  </actuator>
 </transmission>
 <transmission  name="trans_joint_2" >
  <type >
   transmission_interface/SimpleTransmission
  </type>
  <joint  name="joint_2" >
   <hardwareInterface >
    hardware_interface/PositionJointInterface
   </hardwareInterface>
  </joint>
  <actuator  name="motor_joint_2" >
   <mechanicalReduction >
    1
   </mechanicalReduction>
  </actuator>
 </transmission>
 <transmission  name="trans_joint_3" >
  <type >
   transmission_interface/SimpleTransmission
  </type>
  <joint  name="joint_3" >
   <hardwareInterface >
    hardware_interface/PositionJointInterface
   </hardwareInterface>
  </joint>
  <actuator  name="motor_joint_3" >
   <mechanicalReduction >
    1
   </mechanicalReduction>
  </actuator>
 </transmission>
 <transmission  name="trans_joint_4" >
  <type >
   transmission_interface/SimpleTransmission
  </type>
  <joint  name="joint_4" >
   <hardwareInterface >
    hardware_interface/PositionJointInterface
   </hardwareInterface>
  </joint>
  <actuator  name="motor_joint_4" >
   <mechanicalReduction >
    1
   </mechanicalReduction>
  </actuator>
 </transmission>
 <transmission  name="trans_joint_5" >
  <type >
   transmission_interface/SimpleTransmission
  </type>
  <joint  name="joint_5" >
   <hardwareInterface >
    hardware_interface/PositionJointInterface
   </hardwareInterface>
  </joint>
  <actuator  name="motor_joint_5" >
   <mechanicalReduction >
    1
   </mechanicalReduction>
  </actuator>
 </transmission>
 <transmission  name="trans_joint_6" >
  <type >
   transmission_interface/SimpleTransmission
  </type>
  <joint  name="joint_6" >
   <hardwareInterface >
    hardware_interface/PositionJointInterface
   </hardwareInterface>
  </joint>
  <actuator  name="motor_joint_6" >
   <mechanicalReduction >
    1
   </mechanicalReduction>
  </actuator>
 </transmission>
 <gazebo />
 <joint  name="wheeltec_gripper_end_link_joint"  type="fixed" >
  <parent  link="ar3_end_link" />
  <child  link="wheeltec_gripper_base_link" />
 </joint>
 <gazebo />
 <joint  name="realsense2_end_link_joint"  type="fixed" >
  <parent  link="world" />
  <child  link="realsense2_base_link" />
 </joint>
 <link name="wheeltec_gripper_base_link" />
  <joint name="wheeltec_gripper_base_link_joint" type="fixed">
    <parent link="wheeltec_gripper_base_link" />
    <child link="wheeltec_gripper_chaise" />
    <origin rpy="0 -1.5707963267948966 0" xyz="-0.005 0 0.0272" />
  </joint>
  <link name="wheeltec_gripper_chaise">
    <inertial>
      <origin rpy="0 0 0" xyz="0.0293534223009873 0.0090853921588317 0.0106597454256406" />
      <mass value="0.102600550272344" />
      <inertia ixx="5.20788240164367E-05" ixy="6.54090863453443E-09" ixz="4.42197949237897E-10" iyy="3.20696114264544E-05" iyz="-1.34739886846522E-06" izz="4.78657905498745E-05" />
    </inertial>
    <visual>
      <origin rpy="0 0 0" xyz="0 0 0" />
      <geometry>
        <mesh filename="package://wheeltec_gripper_description/meshes/gripperbase.STL" />
      </geometry>
      <material name="">
        <color rgba="0.792156862745098 0.819607843137255 0.933333333333333 1" />
      </material>
    </visual>
    <collision>
      <origin rpy="0 0 0" xyz="0.0293534223009873 0.0090853921588317 0.0106597454256406" />
      <geometry>
        <box size="0.05 0.08 0.045" />
      </geometry>
    </collision>
  </link>
  <gazebo reference="wheeltec_gripper_chaise">
    <material>Gazebo/Yellow</material>
  </gazebo>
  
  <joint name="left_finger_joint" type="revolute">
    <origin rpy="0 0 0" xyz="0.071508 -0.024545 -0.020131" />
    <parent link="wheeltec_gripper_chaise" />
    <child link="left_finger" />
    <axis xyz="2.5729E-05 -0.080001 0.99679" />
    <limit effort="10" lower="0" upper="0.7298" velocity="1.0" />
    <dynamics damping="1" friction="1" />
  </joint>
  <link name="left_finger">
    <inertial>
      <origin rpy="0 0 0" xyz="0.0324201926836488 -0.0145963763975525 0.0293610241174507" />
      <mass value="0.0454654477917792" />
      <inertia ixx="8.54538343821676E-06" ixy="9.08652805486317E-06" ixz="7.29792995722946E-07" iyy="2.33471912608672E-05" iyz="-4.42703368456901E-07" izz="2.88247074076199E-05" />
    </inertial>
    <visual>
      <origin rpy="0 0 0" xyz="0 0 0" />
      <geometry>
        <mesh filename="package://wheeltec_gripper_description/meshes/fingers.STL" />
      </geometry>
      <material name="">
        <color rgba="0.792156862745098 0.819607843137255 0.933333333333333 1" />
      </material>
    </visual>
    <collision>
      <origin rpy="0 0 -0.6" xyz="0.0324201926836488 -0.0145963763975525 0.0293610241174507" />
      <geometry>
        <box size="0.1 0.02 0.04" />
      </geometry>
    </collision>
  </link>
  <link name="wheeltec_gripper_center">
    <visual>
      <origin rpy="0 0 0" xyz="0 0 0" />
      <geometry>
        <box size="0.01 0.01 0.01" />
      </geometry>
    </visual>
  </link>
  <joint name="wheeltec_gripper_center_joint" type="fixed">
    <origin rpy="0 0 0" xyz="0 0 0" />
    <parent link="wheeltec_gripper_chaise" />
    <child link="wheeltec_gripper_center" />
    <axis xyz="0 0 0.001" />
  </joint>
  <gazebo reference="left_finger">
    <material>Gazebo/Green</material>
  </gazebo>
  <transmission name="trans_'left_finger_joint'">
    <type>transmission_interface/SimpleTransmission</type>
    <joint name="left_finger_joint">
      <hardwareInterface>hardware_interface/PositionJointInterface</hardwareInterface>
    </joint>
    <actuator name="motor_left_finger_joint">
      <mechanicalReduction>1</mechanicalReduction>
      <hardwareInterface>hardware_interface/PositionJointInterface</hardwareInterface>
    </actuator>
  </transmission>
  
  <joint name="right_finger_joint" type="revolute">
    <origin rpy="0 0 0.7298" xyz="0.071485 0.047224 -0.01437" />
    <parent link="wheeltec_gripper_chaise" />
    <child link="right_finger" />
    <axis xyz="-2.5729E-05 0.080001 -0.99679" />
    <limit effort="10" lower="0" upper="0.7298" velocity="1.0" />
    <mimic joint="left_finger_joint" multiplier="1" offset="0" />
    <dynamics damping="1" friction="1" />
  </joint>
  <link name="right_finger">
    <inertial>
      <origin rpy="0 0 0" xyz="0.0338378772194818 0.00534175148012631 0.0260745753522557" />
      <mass value="0.0454654472444149" />
      <inertia ixx="6.25574496069598E-06" ixy="-6.61546951322458E-06" ixz="-5.30362302163462E-07" iyy="2.5622104774585E-05" iyz="-2.59716886842376E-07" izz="2.88394198458503E-05" />
    </inertial>
    <visual>
      <origin rpy="0 0 0" xyz="0 0 0" />
      <geometry>
        <mesh filename="package://wheeltec_gripper_description/meshes/fingers.STL" />
      </geometry>
      <material name="">
        <color rgba="0.792156862745098 0.819607843137255 0.933333333333333 1" />
      </material>
    </visual>
    <collision>
      <origin rpy="0 0 -0.3" xyz="0.0338378772194818 -0.02034175148012631 0.020745753522557" />
      <geometry>
        <box size="0.1 0.02 0.04" />
      </geometry>
    </collision>
  </link>
  <gazebo reference="right_finger">
    <material>Gazebo/Red</material>
  </gazebo>
  <gazebo>
    <plugin filename="libroboticsgroup_upatras_gazebo_mimic_joint_plugin.so" name="right_finger_joint_mimic_joint_plugin">
      <joint>left_finger_joint</joint>
      <mimicJoint>right_finger_joint</mimicJoint>
      <multiplier>1.0</multiplier>
      <offset>0</offset>
      <sensitiveness>0.0</sensitiveness>
      <maxEffort>10</maxEffort>
    </plugin>
  </gazebo>
  
  <gazebo>
    <plugin filename="libgazebo_grasp_fix.so" name="gazebo_grasp_fix">
      <arm>
        <arm_name>wheeltec_gripper</arm_name>
        <palm_link>wheeltec_gripper_chaise</palm_link>
        <gripper_link> left_finger </gripper_link>
        <gripper_link> right_finger </gripper_link>
      </arm>
      <disable_collisions_on_attach>false</disable_collisions_on_attach>
      <forces_angle_tolerance>100</forces_angle_tolerance>
      <update_rate>10</update_rate>
      <grip_count_threshold>3</grip_count_threshold>
      <max_grip_count>10</max_grip_count>
      <release_tolerance>0.001</release_tolerance>
      <contact_topic>__default_topic__</contact_topic>
    </plugin>
  </gazebo>
<link name="realsense2_base_link" />
  <material name="camera_aluminum">
    <color rgba="0.5 0.5 0.5 1" />
  </material>
  
  <joint name="camera_joint" type="fixed">
    <origin rpy="0 1.5707963267948966 0" xyz="-0.1 -0.35 0.75" />
    <parent link="realsense2_base_link" />
    <child link="camera_bottom_screw_frame" />
  </joint>
  <link name="camera_bottom_screw_frame" />
  <joint name="camera_link_joint" type="fixed">
    <origin rpy="0 0 0" xyz="0 0.0175 0.0125" />
    <parent link="camera_bottom_screw_frame" />
    <child link="camera_link" />
  </joint>
  <link name="camera_link">
    <visual>
      <origin rpy="1.5707963267948966 0 1.5707963267948966" xyz="0.0149 -0.0175 0" />
      <geometry>
        
        <mesh filename="package://realsense2_description/meshes/d435.dae" />
        
      </geometry>
      <material name="camera_aluminum" />
    </visual>
    <collision>
      <origin rpy="0 0 0" xyz="0 -0.0175 0" />
      <geometry>
        <box size="0.02505 0.09 0.025" />
      </geometry>
    </collision>
    <inertial>
      
      <mass value="0.564" />
      <origin xyz="0 0 0" />
      <inertia ixx="0.003881243" ixy="0.0" ixz="0.0" iyy="0.000498940" iyz="0.0" izz="0.003879257" />
    </inertial>
  </link>
  
  <joint name="camera_depth_joint" type="fixed">
    <origin rpy="0 0 0" xyz="0 0 0" />
    <parent link="camera_link" />
    <child link="camera_depth_frame" />
  </joint>
  <link name="camera_depth_frame" />
  <joint name="camera_depth_optical_joint" type="fixed">
    <origin rpy="-1.5707963267948966 0 -1.5707963267948966" xyz="0 0 0" />
    <parent link="camera_depth_frame" />
    <child link="camera_depth_optical_frame" />
  </joint>
  <link name="camera_depth_optical_frame" />
  
  <joint name="camera_left_ir_joint" type="fixed">
    <origin rpy="0 0 0" xyz="0 0.0 0" />
    <parent link="camera_depth_frame" />
    <child link="camera_left_ir_frame" />
  </joint>
  <link name="camera_left_ir_frame" />
  <joint name="camera_left_ir_optical_joint" type="fixed">
    <origin rpy="-1.5707963267948966 0 -1.5707963267948966" xyz="0 0 0" />
    <parent link="camera_left_ir_frame" />
    <child link="camera_left_ir_optical_frame" />
  </joint>
  <link name="camera_left_ir_optical_frame" />
  
  <joint name="camera_right_ir_joint" type="fixed">
    <origin rpy="0 0 0" xyz="0 -0.05 0" />
    <parent link="camera_depth_frame" />
    <child link="camera_right_ir_frame" />
  </joint>
  <link name="camera_right_ir_frame" />
  <joint name="camera_right_ir_optical_joint" type="fixed">
    <origin rpy="-1.5707963267948966 0 -1.5707963267948966" xyz="0 0 0" />
    <parent link="camera_right_ir_frame" />
    <child link="camera_right_ir_optical_frame" />
  </joint>
  <link name="camera_right_ir_optical_frame" />
  
  <joint name="camera_color_joint" type="fixed">
    <origin rpy="0 0 0" xyz="0 0.015 0" />
    <parent link="camera_depth_frame" />
    <child link="camera_color_frame" />
  </joint>
  <link name="camera_color_frame" />
  <joint name="camera_color_optical_joint" type="fixed">
    <origin rpy="-1.5707963267948966 0 -1.5707963267948966" xyz="0 0 0" />
    <parent link="camera_color_frame" />
    <child link="camera_color_optical_frame" />
  </joint>
  <link name="camera_color_optical_frame" />
  <gazebo reference="camera_link">
    <self_collide>0</self_collide>
    <enable_wind>0</enable_wind>
    <kinematic>0</kinematic>
    <gravity>1</gravity>
    
    <mu2>1</mu2>
    <fdir1>0 0 0</fdir1>
    
    <kp>1e+13</kp>
    <kd>1</kd>
    
    <sensor name="cameracolor" type="camera">
      <camera name="camera">
        <horizontal_fov>1.2112585008840648</horizontal_fov>
        <image>
          <width>640</width>
          <height>480</height>
          <format>RGB_INT8</format>
        </image>
        <clip>
          <near>0.1</near>
          <far>100</far>
        </clip>
        <noise>
          <type>gaussian</type>
          <mean>0.0</mean>
          <stddev>0.007</stddev>
        </noise>
      </camera>
      <always_on>1</always_on>
      <update_rate>30</update_rate>
      <visualize>1</visualize>
    </sensor>
    <sensor name="cameraired1" type="camera">
      <camera name="camera">
        <horizontal_fov>1.4870205226991688</horizontal_fov>
        <image>
          <width>1280</width>
          <height>720</height>
          <format>L_INT8</format>
        </image>
        <clip>
          <near>0.1</near>
          <far>100</far>
        </clip>
        <noise>
          <type>gaussian</type>
          <mean>0.0</mean>
          <stddev>0.05</stddev>
        </noise>
      </camera>
      <always_on>1</always_on>
      <update_rate>90</update_rate>
      <visualize>0</visualize>
    </sensor>
    <sensor name="cameraired2" type="camera">
      <camera name="camera">
        <horizontal_fov>1.4870205226991688</horizontal_fov>
        <image>
          <width>1280</width>
          <height>720</height>
          <format>L_INT8</format>
        </image>
        <clip>
          <near>0.1</near>
          <far>100</far>
        </clip>
        <noise>
          <type>gaussian</type>
          <mean>0.0</mean>
          <stddev>0.05</stddev>
        </noise>
      </camera>
      <always_on>1</always_on>
      <update_rate>90</update_rate>
      <visualize>0</visualize>
    </sensor>
    <sensor name="cameradepth" type="depth">
      <camera name="camera">
        <horizontal_fov>1.4870205226991688</horizontal_fov>
        <image>
          <width>1280</width>
          <height>720</height>
        </image>
        <clip>
          <near>0.1</near>
          <far>100</far>
        </clip>
        <noise>
          <type>gaussian</type>
          <mean>0.0</mean>
          <stddev>0.100</stddev>
        </noise>
      </camera>
      <always_on>1</always_on>
      <update_rate>90</update_rate>
      <visualize>0</visualize>
    </sensor>
  </gazebo>
  <gazebo>
    <plugin filename="librealsense_gazebo_plugin.so" name="camera">
      <prefix>camera</prefix>
      <depthUpdateRate>30.0</depthUpdateRate>
      <colorUpdateRate>30.0</colorUpdateRate>
      <infraredUpdateRate>30.0</infraredUpdateRate>
      <depthTopicName>depth/image_raw</depthTopicName>
      <depthCameraInfoTopicName>depth/camera_info</depthCameraInfoTopicName>
      <colorTopicName>color/image_raw</colorTopicName>
      <colorCameraInfoTopicName>color/camera_info</colorCameraInfoTopicName>
      <infrared1TopicName>infra1/image_raw</infrared1TopicName>
      <infrared1CameraInfoTopicName>infra1/camera_info</infrared1CameraInfoTopicName>
      <infrared2TopicName>infra2/image_raw</infrared2TopicName>
      <infrared2CameraInfoTopicName>infra2/camera_info</infrared2CameraInfoTopicName>
      <colorOpticalframeName>camera_color_optical_frame</colorOpticalframeName>
      <depthOpticalframeName>camera_depth_optical_frame</depthOpticalframeName>
      <infrared1OpticalframeName>camera_left_ir_optical_frame</infrared1OpticalframeName>
      <infrared2OpticalframeName>camera_right_ir_optical_frame</infrared2OpticalframeName>
      <rangeMinDepth>0.2</rangeMinDepth>
      <rangeMaxDepth>10.0</rangeMaxDepth>
      <pointCloud>False</pointCloud>
      <pointCloudTopicName>depth/color/points</pointCloudTopicName>
      <pointCloudCutoff>0.25</pointCloudCutoff>
      <pointCloudCutoffMax>9.0</pointCloudCutoffMax>
    </plugin>
  </gazebo>

</robot>